<!DOCTYPE html>

<!-- 基準URI -->
<base href="https://takaha-q.github.io/">

<!-- スタイルシート -->
<link rel="stylesheet" href="Sytle001.css" type="text/css">

<!-- スクリプト -->
<!-- タイトル表示 -->
<script src="MakeTitle.js" type="text/javascript"></script>

<!-- 目次表示 -->
<script src="MakeToc_L.js" type="text/javascript"></script>

<!-- ページタイトル(ページ内表示) -->
<span id="title"></span>

<!-- リンク(ホームに戻る) -->
<a href="index.html">ホームに戻る</a><br>

<!-- 出典 -->

<!-- 関連 -->
<h6>関連 :</h6>
<a href="TIPS/C・C++/例外クラス.html">例外クラス</a>

<!-- 目次 -->
<h6>目次 :</h6>
<div id="toc"></div>
<hr>
<!-- 本文ここから -->

<h2>例外処理(exception handling)とは</h2>
実行時エラーを管理し、処理する機構。<br>
エラー(例外)発生時の処理を体系的に、また集約して実装することができる。<br>
C++に限らず、オブジェクト指向言語においては一般的な概念。<br>
尚、例外を発行することを慣例的に「例外を投げる(throw exception)」という。<br>

<h2>例外処理の原則</h2>
C++における例外処理の原則は以下の通りである。
<ul>
    <li>例外(エラー)の発生を監視したい処理を try 節内に記述すると、例外が発生した場合即座に try 節を抜け、直後の catch 節にジャンプする。
        <ul>
            <li>try 節内における、例外発生箇所より後の処理は実行されない。</li>
            <li>catch 節は必ず try 節の直後に記述する必要がある。</li>
        </ul>
    </li>
    <li value="2">catch 節では宣言した型の例外のみ捕捉可能。複数の catch 節を書き連ねることで、発生した例外の型に応じて後処理を区分できる。
        <ul>
            <li>即ち、実行される catch 節は最大でも1つ。</li>
            <li>捕捉できない型の例外が発生した場合は、プログラムが不正終了する。</li>
        </ul>
    </li>
    <li value="3">catch 節以降に処理が存在する場合、例外が発生しなければ try 節実行後、例外が発生すれば catch 節実行後に実行される。
        <ul>
            <li>即ち、記述された通りの順序で実行される。</li>
        </ul>
    </li>
    <li value="4">システム内部で発生する例外以外に、throw 句を用いることで任意の例外を発生させる(投げる)ことができる。</li>
</ul>

<h2>基本的な例</h2>
<img src="https://raw.githubusercontent.com/Takaha-Q/Takaha-Q.github.io/main/_Img/CPP/exception_handling/exception_handling_01.png" alt="画像"><br>

上記の例では、関数 func() 中の try 節に含まれる func2() 、DoSomething() が例外監視対象となる。<br>
func2() では内部で int 型例外を投げ( throw )ており、try 節に続く catch (int ex) 節で例外が捕捉される。<br>
(int 型と異なる型の例外が投げられた場合は、後続の catch (string ex) 節、または catch (...) 節で捕捉される。)

<h2>例外の投げなおし</h2>
try ブロックで発生した例外を処理した後、さらに外側に例外を投げることができる。<br>
当然、try ブロックは(コールスタック全体で)ネストしている必要がある。<br>

<h3>捕捉した例外と異なる例外を投げる</h3>
<img src="https://raw.githubusercontent.com/Takaha-Q/Takaha-Q.github.io/main/_Img/CPP/exception_handling/exception_handling_02.png" alt="画像"><br>
catch 節内に throw 句を記述することで、さらに外側に例外を投げる。<br>
このとき、捕捉した例外と型や値が一致している必要はない。

<h3>捕捉した例外をそのまま投げなおす</h3>
捕捉した例外をそのまま投げなおす場合は、<b>throw のみ</b>を記述する。

<div class="code">
<kwd>void</kwd> func1()
{
    <kwd>try</kwd>
    {
        <cmt>// ここで例外発生</cmt>
        func2();
    }
    <kwd>catch</kwd> (exception ex)
    {
        <cmt>// 例外を投げなおす</cmt>
        <kwd>throw</kwd>;

        <cmt>// これは誤り
        // throw ex;</cmt>
    }
}
</div>

上記のコードでは例外 ex を捕捉し、外側に投げなおしている。<br>
このとき<span class="code">throw ex;</span>とすると、ex が投げられた時点でのコールスタック情報( func2() )しか記録されないため、<br>
func1() が例外を投げ(なおし)たことがわからなくなる。<br>
単に<span class="code">throw;</span>とすることで、投げなおした func1() の情報も追加される。<br>
投げなおされる例外の型は ex と共通である。

<h2>例外送出有無の表明 ( noexcept )</h2>
<b>noexcept</b> 句を使用することで、関数が例外を送出しない(または逆に、する可能性がある)ことを明確化することができる。<br>
例外を送出しないことを明示すると巻き戻すためのスタックが確保されなくなるため、スタック使用量を削減することができる。<br>

<p class="code">
<cmt>// 例外を送出しない</cmt>
<kwd>void</kwd> f() <kwd>noexcept</kwd>;
<kwd>void</kwd> f() <kwd>noexcept</kwd>(<kwd>true</kwd>);

<cmt>// 例外を送出する(可能性がある)</cmt>
<kwd>void</kwd> f() <kwd>noexcept</kwd>(<kwd>false</kwd>);
<kwd>void</kwd> f();
</p>

過去には、throw 句を用いて送出例外の型を制限する記法も存在したが、これはあまり有用ではないことから<br>
C++11で非推奨となり、C++17で削除された。

<h2>C++標準の例外クラス</h2>
C++の標準ライブラリには、例外として送出するためのクラス(例外オブジェクト)が定義されている。詳細は<a href="TIPS/C・C++/例外クラス.html">ここ</a>を参照。
